<?xml version="1.0" ?>
<sdf version="1.8">
  <model name="my_robot">
    <pose>0 0 0.15 0 0 0</pose> 

    <link name="base_link">
      <inertial>
        <mass>5.0</mass>
        <inertia>
          <ixx>0.1</ixx><ixy>0</ixy><ixz>0</ixz>
          <iyy>0.1</iyy><iyz>0</iyz>
          <izz>0.15</izz>
        </inertia>
      </inertial>
      <visual name="visual">
        <geometry><box><size>0.4 0.3 0.1</size></box></geometry>
        <material><ambient>0 0 1 1</ambient><diffuse>0 0 1 1</diffuse></material>
      </visual>
      <collision name="collision">
        <geometry><box><size>0.4 0.3 0.1</size></box></geometry>
        <surface>
          <friction>
            <ode>
              <mu>0.01</mu> <mu2>0.01</mu2>
            </ode>
          </friction>
          <contact>
            <ode>
              <kp>1000000.0</kp>
              <kd>1.0</kd>
              <max_vel>0.01</max_vel> <min_depth>0.001</min_depth> </ode>
          </contact>
        </surface>
      </collision>
    </link>

    <link name="left_wheel">
      <pose>-0.1 0.22 -0.05 0 0 0</pose> 
      <inertial>
        <mass>0.8</mass>
        <inertia><ixx>0.002</ixx><iyy>0.002</iyy><izz>0.002</izz></inertia>
      </inertial>
      <visual name="visual">
        <pose>0 0 0 1.5708 0 0</pose>
        <geometry><cylinder><radius>0.1</radius><length>0.05</length></cylinder></geometry>
        <material><ambient>0 0 0 1</ambient><diffuse>0 0 0 1</diffuse></material>
      </visual>
      <collision name="collision">
        <pose>0 0 0 1.5708 0 0</pose>
        <geometry><cylinder><radius>0.1</radius><length>0.05</length></cylinder></geometry>
        <surface>
          <friction><ode><mu>1.0</mu><mu2>1.0</mu2></ode></friction>
        </surface>
      </collision>
    </link>

    <link name="right_wheel">
      <pose>-0.1 -0.22 -0.05 0 0 0</pose>
      <inertial>
        <mass>0.8</mass>
        <inertia><ixx>0.002</ixx><iyy>0.002</iyy><izz>0.002</izz></inertia>
      </inertial>
      <visual name="visual">
        <pose>0 0 0 1.5708 0 0</pose>
        <geometry><cylinder><radius>0.1</radius><length>0.05</length></cylinder></geometry>
        <material><ambient>0 0 0 1</ambient><diffuse>0 0 0 1</diffuse></material>
      </visual>
      <collision name="collision">
        <pose>0 0 0 1.5708 0 0</pose>
        <geometry><cylinder><radius>0.1</radius><length>0.05</length></cylinder></geometry>
        <surface>
          <friction><ode><mu>1.0</mu><mu2>1.0</mu2></ode></friction>
        </surface>
      </collision>
    </link>

    <link name="caster_wheel">
      <pose>0.15 0 -0.1 0 0 0</pose>
      <inertial>
        <mass>0.5</mass> <inertia><ixx>0.001</ixx><iyy>0.001</iyy><izz>0.001</izz></inertia>
      </inertial>
      <visual name="visual">
        <geometry><sphere><radius>0.05</radius></sphere></geometry>
        <material><ambient>0.8 0.8 0.8 1</ambient></material>
      </visual>
      <collision name="collision">
        <geometry><sphere><radius>0.05</radius></sphere></geometry>
        <surface>
          <friction>
            <ode>
              <mu>0.0</mu> <mu2>0.0</mu2>
            </ode>
          </friction>
          <contact>
            <ode>
              <kp>1000000.0</kp> <kd>100.0</kd>
            </ode>
          </contact>
        </surface>
      </collision>
    </link>

    <link name="camera_link">
      <pose>0.2 0 0.05 0 0 0</pose>
      <sensor name="camera" type="camera">
        <topic>/model/my_robot/camera/image_raw</topic>
        <camera>
          <horizontal_fov>1.047</horizontal_fov>
          <image><width>640</width><height>480</height></image>
        </camera>
        <always_on>1</always_on>
        <update_rate>20</update_rate>
        <visualize>true</visualize>
      </sensor>
    </link>

    <joint name="left_wheel_joint" type="revolute">
      <parent>base_link</parent><child>left_wheel</child>
      <axis><xyz>0 1 0</xyz><limit><lower>-1e16</lower><upper>1e16</upper></limit></axis>
    </joint>
    <joint name="right_wheel_joint" type="revolute">
      <parent>base_link</parent><child>right_wheel</child>
      <axis><xyz>0 1 0</xyz><limit><lower>-1e16</lower><upper>1e16</upper></limit></axis>
    </joint>
    <joint name="caster_wheel_joint" type="ball">
      <parent>base_link</parent><child>caster_wheel</child>
    </joint>
    <joint name="camera_joint" type="fixed">
      <parent>base_link</parent><child>camera_link</child>
    </joint>

    <plugin filename="gz-sim-diff-drive-system" name="gz::sim::systems::DiffDrive">
      <left_joint>left_wheel_joint</left_joint>
      <right_joint>right_wheel_joint</right_joint>
      <wheel_separation>0.44</wheel_separation> <wheel_radius>0.1</wheel_radius>
      <topic>/model/my_robot/cmd_vel</topic>
      <odom_topic>/model/my_robot/odometry</odom_topic>
    </plugin>
  </model>
</sdf>